[2024-05-15T20:06:03.101+0000] {scheduler_job_runner.py:781} ERROR - Executor reports task instance <TaskInstance: ademe_transform_data.transform_data_task scheduled__2024-05-15T20:03:00+00:00 [queued]> finished (failed) although the task says it's queued. (Info: None) Was the task killed externally?
