[2024-05-15T11:26:05.444+0000] {scheduler_job_runner.py:781} ERROR - Executor reports task instance <TaskInstance: ademe_models.train_model_task scheduled__2024-05-14T00:00:00+00:00 [queued]> finished (failed) although the task says it's queued. (Info: None) Was the task killed externally?
