[2024-05-14T21:29:44.114+0000] {taskinstance.py:1979} INFO - Dependencies all met for dep_context=non-requeueable deps ti=<TaskInstance: ademe_models.train_model_task manual__2024-05-14T21:29:34.818235+00:00 [queued]>
[2024-05-14T21:29:44.128+0000] {taskinstance.py:1979} INFO - Dependencies all met for dep_context=requeueable deps ti=<TaskInstance: ademe_models.train_model_task manual__2024-05-14T21:29:34.818235+00:00 [queued]>
[2024-05-14T21:29:44.129+0000] {taskinstance.py:2193} INFO - Starting attempt 1 of 1
[2024-05-14T21:29:44.154+0000] {taskinstance.py:2217} INFO - Executing <Task(PythonOperator): train_model_task> on 2024-05-14 21:29:34.818235+00:00
[2024-05-14T21:29:44.183+0000] {standard_task_runner.py:60} INFO - Started process 627 to run task
[2024-05-14T21:29:44.208+0000] {standard_task_runner.py:87} INFO - Running: ['***', 'tasks', 'run', 'ademe_models', 'train_model_task', 'manual__2024-05-14T21:29:34.818235+00:00', '--job-id', '38', '--raw', '--subdir', 'DAGS_FOLDER/predict_data.py', '--cfg-path', '/tmp/tmpyi7oowqh']
[2024-05-14T21:29:44.210+0000] {standard_task_runner.py:88} INFO - Job 38: Subtask train_model_task
[2024-05-14T21:29:44.355+0000] {task_command.py:423} INFO - Running <TaskInstance: ademe_models.train_model_task manual__2024-05-14T21:29:34.818235+00:00 [running]> on host 0f2797502ce2
[2024-05-14T21:29:44.613+0000] {taskinstance.py:2513} INFO - Exporting env vars: AIRFLOW_CTX_DAG_OWNER='***' AIRFLOW_CTX_DAG_ID='ademe_models' AIRFLOW_CTX_TASK_ID='train_model_task' AIRFLOW_CTX_EXECUTION_DATE='2024-05-14T21:29:34.818235+00:00' AIRFLOW_CTX_TRY_NUMBER='1' AIRFLOW_CTX_DAG_RUN_ID='manual__2024-05-14T21:29:34.818235+00:00'
[2024-05-14T21:29:44.752+0000] {logging_mixin.py:188} INFO - Empty DataFrame
Columns: []
Index: []
[2024-05-14T21:29:44.977+0000] {logging_mixin.py:188} WARNING - 2024/05/14 21:29:44 WARNING mlflow.utils.git_utils: Failed to import Git (the Git executable is probably not on your PATH), so Git SHA is not available. Error: Failed to initialize: Bad git executable.
The git executable must be specified in one of the following ways:
    - be included in your $PATH
    - be set via $GIT_PYTHON_GIT_EXECUTABLE
    - explicitly set via git.refresh(<full-path-to-git-executable>)

All git commands will error until this is rectified.

This initial message can be silenced or aggravated in the future by setting the
$GIT_PYTHON_REFRESH environment variable. Use one of the following values:
    - quiet|q|silence|s|silent|none|n|0: for no message or exception
    - warn|w|warning|log|l|1: for a warning message (logging level CRITICAL, displayed by default)
    - error|e|exception|raise|r|2: for a raised exception

Example:
    export GIT_PYTHON_REFRESH=quiet
[2024-05-14T21:29:45.091+0000] {taskinstance.py:2731} ERROR - Task failed with exception
Traceback (most recent call last):
  File "/home/airflow/.local/lib/python3.8/site-packages/airflow/models/taskinstance.py", line 444, in _execute_task
    result = _execute_callable(context=context, **execute_callable_kwargs)
  File "/home/airflow/.local/lib/python3.8/site-packages/airflow/models/taskinstance.py", line 414, in _execute_callable
    return execute_callable(context=context, **execute_callable_kwargs)
  File "/home/airflow/.local/lib/python3.8/site-packages/airflow/operators/python.py", line 200, in execute
    return_value = self.execute_callable()
  File "/home/airflow/.local/lib/python3.8/site-packages/airflow/operators/python.py", line 217, in execute_callable
    return self.python_callable(*self.op_args, **self.op_kwargs)
  File "/opt/airflow/dags/predict_data.py", line 199, in train_model
    train = TrainDPE(data)
  File "/opt/airflow/dags/predict_data.py", line 58, in __init__
    data = data[data[target] >= 0].copy()
  File "/home/airflow/.local/lib/python3.8/site-packages/pandas/core/frame.py", line 3761, in __getitem__
    indexer = self.columns.get_loc(key)
  File "/home/airflow/.local/lib/python3.8/site-packages/pandas/core/indexes/range.py", line 349, in get_loc
    raise KeyError(key)
KeyError: 'etiquette_ges'
[2024-05-14T21:29:45.124+0000] {taskinstance.py:1149} INFO - Marking task as FAILED. dag_id=ademe_models, task_id=train_model_task, execution_date=20240514T212934, start_date=20240514T212944, end_date=20240514T212945
[2024-05-14T21:29:45.193+0000] {standard_task_runner.py:107} ERROR - Failed to execute job 38 for task train_model_task ('etiquette_ges'; 627)
[2024-05-14T21:29:45.224+0000] {local_task_job_runner.py:234} INFO - Task exited with return code 1
[2024-05-14T21:29:45.312+0000] {taskinstance.py:3312} INFO - 0 downstream tasks scheduled from follow-on schedule check
