[2024-05-14T20:54:52.853+0000] {taskinstance.py:1979} INFO - Dependencies all met for dep_context=non-requeueable deps ti=<TaskInstance: live_ademe.interrogate_api manual__2024-05-14T20:54:42.161003+00:00 [queued]>
[2024-05-14T20:54:52.864+0000] {taskinstance.py:1979} INFO - Dependencies all met for dep_context=requeueable deps ti=<TaskInstance: live_ademe.interrogate_api manual__2024-05-14T20:54:42.161003+00:00 [queued]>
[2024-05-14T20:54:52.864+0000] {taskinstance.py:2193} INFO - Starting attempt 1 of 2
[2024-05-14T20:54:52.880+0000] {taskinstance.py:2217} INFO - Executing <Task(PythonOperator): interrogate_api> on 2024-05-14 20:54:42.161003+00:00
[2024-05-14T20:54:52.888+0000] {standard_task_runner.py:60} INFO - Started process 74 to run task
[2024-05-14T20:54:52.894+0000] {standard_task_runner.py:87} INFO - Running: ['***', 'tasks', 'run', 'live_ademe', 'interrogate_api', 'manual__2024-05-14T20:54:42.161003+00:00', '--job-id', '14', '--raw', '--subdir', 'DAGS_FOLDER/load_data.py', '--cfg-path', '/tmp/tmpb_cigsth']
[2024-05-14T20:54:52.896+0000] {standard_task_runner.py:88} INFO - Job 14: Subtask interrogate_api
[2024-05-14T20:54:52.951+0000] {task_command.py:423} INFO - Running <TaskInstance: live_ademe.interrogate_api manual__2024-05-14T20:54:42.161003+00:00 [running]> on host 0f2797502ce2
[2024-05-14T20:54:53.030+0000] {taskinstance.py:2513} INFO - Exporting env vars: AIRFLOW_CTX_DAG_EMAIL='***@example.com' AIRFLOW_CTX_DAG_OWNER='***' AIRFLOW_CTX_DAG_ID='live_ademe' AIRFLOW_CTX_TASK_ID='interrogate_api' AIRFLOW_CTX_EXECUTION_DATE='2024-05-14T20:54:42.161003+00:00' AIRFLOW_CTX_TRY_NUMBER='1' AIRFLOW_CTX_DAG_RUN_ID='manual__2024-05-14T20:54:42.161003+00:00'
[2024-05-14T20:54:53.032+0000] {taskinstance.py:2731} ERROR - Task failed with exception
Traceback (most recent call last):
  File "/home/airflow/.local/lib/python3.8/site-packages/airflow/models/taskinstance.py", line 444, in _execute_task
    result = _execute_callable(context=context, **execute_callable_kwargs)
  File "/home/airflow/.local/lib/python3.8/site-packages/airflow/models/taskinstance.py", line 414, in _execute_callable
    return execute_callable(context=context, **execute_callable_kwargs)
  File "/home/airflow/.local/lib/python3.8/site-packages/airflow/operators/python.py", line 200, in execute
    return_value = self.execute_callable()
  File "/home/airflow/.local/lib/python3.8/site-packages/airflow/operators/python.py", line 217, in execute_callable
    return self.python_callable(*self.op_args, **self.op_kwargs)
  File "/opt/airflow/dags/load_data.py", line 67, in interrogate_api
    url = json.load(file)
  File "/usr/local/lib/python3.8/json/__init__.py", line 293, in load
    return loads(fp.read(),
  File "/usr/local/lib/python3.8/json/__init__.py", line 357, in loads
    return _default_decoder.decode(s)
  File "/usr/local/lib/python3.8/json/decoder.py", line 337, in decode
    obj, end = self.raw_decode(s, idx=_w(s, 0).end())
  File "/usr/local/lib/python3.8/json/decoder.py", line 353, in raw_decode
    obj, end = self.scan_once(s, idx)
json.decoder.JSONDecodeError: Expecting property name enclosed in double quotes: line 2 column 2 (char 3)
[2024-05-14T20:54:53.041+0000] {taskinstance.py:1149} INFO - Marking task as UP_FOR_RETRY. dag_id=live_ademe, task_id=interrogate_api, execution_date=20240514T205442, start_date=20240514T205452, end_date=20240514T205453
[2024-05-14T20:54:53.057+0000] {standard_task_runner.py:107} ERROR - Failed to execute job 14 for task interrogate_api (Expecting property name enclosed in double quotes: line 2 column 2 (char 3); 74)
[2024-05-14T20:54:53.106+0000] {local_task_job_runner.py:234} INFO - Task exited with return code 1
[2024-05-14T20:54:53.148+0000] {taskinstance.py:3312} INFO - 0 downstream tasks scheduled from follow-on schedule check
