[2024-05-15T19:53:14.230+0000] {taskinstance.py:1979} INFO - Dependencies all met for dep_context=non-requeueable deps ti=<TaskInstance: ademe_transform_data.transform_data_task scheduled__2024-05-15T19:48:00+00:00 [queued]>
[2024-05-15T19:53:14.254+0000] {taskinstance.py:1979} INFO - Dependencies all met for dep_context=requeueable deps ti=<TaskInstance: ademe_transform_data.transform_data_task scheduled__2024-05-15T19:48:00+00:00 [queued]>
[2024-05-15T19:53:14.255+0000] {taskinstance.py:2193} INFO - Starting attempt 1 of 1
[2024-05-15T19:53:14.289+0000] {taskinstance.py:2217} INFO - Executing <Task(PythonOperator): transform_data_task> on 2024-05-15 19:48:00+00:00
[2024-05-15T19:53:14.299+0000] {standard_task_runner.py:60} INFO - Started process 59 to run task
[2024-05-15T19:53:14.309+0000] {standard_task_runner.py:87} INFO - Running: ['***', 'tasks', 'run', 'ademe_transform_data', 'transform_data_task', 'scheduled__2024-05-15T19:48:00+00:00', '--job-id', '63', '--raw', '--subdir', 'DAGS_FOLDER/tansform_data.py', '--cfg-path', '/tmp/tmpk86tdyjp']
[2024-05-15T19:53:14.311+0000] {standard_task_runner.py:88} INFO - Job 63: Subtask transform_data_task
[2024-05-15T19:53:14.471+0000] {task_command.py:423} INFO - Running <TaskInstance: ademe_transform_data.transform_data_task scheduled__2024-05-15T19:48:00+00:00 [running]> on host 0f2797502ce2
[2024-05-15T19:53:14.624+0000] {taskinstance.py:2513} INFO - Exporting env vars: AIRFLOW_CTX_DAG_OWNER='***' AIRFLOW_CTX_DAG_ID='ademe_transform_data' AIRFLOW_CTX_TASK_ID='transform_data_task' AIRFLOW_CTX_EXECUTION_DATE='2024-05-15T19:48:00+00:00' AIRFLOW_CTX_TRY_NUMBER='1' AIRFLOW_CTX_DAG_RUN_ID='scheduled__2024-05-15T19:48:00+00:00'
[2024-05-15T19:53:17.673+0000] {taskinstance.py:2731} ERROR - Task failed with exception
Traceback (most recent call last):
  File "/home/airflow/.local/lib/python3.8/site-packages/airflow/models/taskinstance.py", line 444, in _execute_task
    result = _execute_callable(context=context, **execute_callable_kwargs)
  File "/home/airflow/.local/lib/python3.8/site-packages/airflow/models/taskinstance.py", line 414, in _execute_callable
    return execute_callable(context=context, **execute_callable_kwargs)
  File "/home/airflow/.local/lib/python3.8/site-packages/airflow/operators/python.py", line 200, in execute
    return_value = self.execute_callable()
  File "/home/airflow/.local/lib/python3.8/site-packages/airflow/operators/python.py", line 217, in execute_callable
    return self.python_callable(*self.op_args, **self.op_kwargs)
  File "/opt/airflow/dags/tansform_data.py", line 27, in transform
    db = Database()
  File "/opt/airflow/dags/db_init.py", line 17, in __init__
    self.connection = psycopg2.connect(**db_params)
  File "/home/airflow/.local/lib/python3.8/site-packages/psycopg2/__init__.py", line 122, in connect
    conn = _connect(dsn, connection_factory=connection_factory, **kwasync)
psycopg2.OperationalError: connection to server at "mlopsadmin.postgres.database.azure.com" (20.231.213.12), port 5432 failed: Connection refused
	Is the server running on that host and accepting TCP/IP connections?

[2024-05-15T19:53:17.688+0000] {taskinstance.py:1149} INFO - Marking task as FAILED. dag_id=ademe_transform_data, task_id=transform_data_task, execution_date=20240515T194800, start_date=20240515T195314, end_date=20240515T195317
[2024-05-15T19:53:17.708+0000] {standard_task_runner.py:107} ERROR - Failed to execute job 63 for task transform_data_task (connection to server at "mlopsadmin.postgres.database.azure.com" (20.231.213.12), port 5432 failed: Connection refused
	Is the server running on that host and accepting TCP/IP connections?
; 59)
[2024-05-15T19:53:17.745+0000] {local_task_job_runner.py:234} INFO - Task exited with return code 1
[2024-05-15T19:53:17.764+0000] {taskinstance.py:3312} INFO - 0 downstream tasks scheduled from follow-on schedule check
